<?xml version="1.0"?>
<!-- <robot name="head_2d"> -->
<robot xmlns:xacro="http://www.ros.org/wiki/xacro" name="head_2d">

    <xacro:include filename="inertial_macros.xacro" />

    <material name="white">
        <color rgba="1 1 1 1" />
    </material>

    <material name="orange">
        <color rgba="1 0.3 0.1 1" />
    </material>

    <material name="blue">
        <color rgba="0.2 0.2 1 1" />
    </material>

    <material name="black">
        <color rgba="0 0 0 1" />
    </material>
    
    <!--BASE LINK-->

    <link name="base_link">

    </link>

    <joint name="chassis_joint" type="fixed">
        <parent link="base_link"/>
        <child link="chassis"/>
        <origin xyz="-0.23 0 0"/>
    </joint>

    <!--CHASSIS LINK-->

    <link name="chassis">
        <visual>
            <origin xyz="0.26 0 0.12"/>
            <geometry>
                <box size ="0.52 0.43 0.3"/>
            </geometry>
            <material name="white"/>
        </visual>
        <collision>
            <origin xyz="0.26 0 0.12"/>
            <geometry>
                <box size ="0.52 0.43 0.3"/>
            </geometry>
            
        </collision>
        <xacro:inertial_box mass="2" x="0.52" y="0.43" z="0.3">
            <origin xyz="0.26 0 0.12"/>
        </xacro:inertial_box>
    </link>
    <joint name="left_wheel_joint" type="continuous">
        <parent link="base_link"/>
        <child link="left_wheel"/>
        <origin xyz="0 0.165 0" rpy="-${pi/2} 0 0"/>
        <axis xyz="0 0 1"/>
    </joint>

    <!--LEFT WHEEL LINK-->
    <link name="left_wheel">
        <visual>
        
            <geometry>
                <cylinder radius="0.0575" length="0.045"/>
            </geometry>
            <material name="blue"/>
        </visual>
        <collision>
        
            <geometry>
                <cylinder radius="0.0575" length="0.045"/>
            </geometry>
            
        </collision>
        <xacro:inertial_cylinder mass="0.1" radius="0.0575" length="0.045">
            <origin xyz="0 0 0" rpy="0 0 0"/>
        </xacro:inertial_cylinder>
    </link>

    <!--RIGHT WHEEL LINK-->
    <joint name="right_wheel_joint" type="continuous">
        <parent link="base_link"/>
        <child link="right_wheel"/>
        <origin xyz="0 -0.165 0" rpy="${pi/2} 0 0"/>
        <axis xyz="0 0 -1"/>
    </joint>

    <link name="right_wheel">
        <visual>
        
            <geometry>
                <cylinder radius="0.0575" length="0.045"/>
            </geometry>
            <material name="blue"/>
        </visual>
        <collision>
        
            <geometry>
                <cylinder radius="0.0575" length="0.045"/>
            </geometry>
            
        </collision>
        <xacro:inertial_cylinder mass="0.1" radius="0.0575" length="0.045">
            <origin xyz="0 0 0" rpy="0 0 0"/>
        </xacro:inertial_cylinder>
    </link>

    <!--FRONT CASTER WHEEL LINK-->
    <joint name="front_caster_wheel_joint" type="fixed">
        <parent link="base_link"/>
        <child link="front_caster_wheel"/>
        <origin xyz="0.1875 0 0"/>
    </joint>

    <link name="front_caster_wheel">
        <visual>
            <geometry>
                <sphere radius="0.0575"/>
            </geometry>
            <material name="black"/>
        </visual>
        <collision>
            <geometry>
                <sphere radius="0.0575"/>
            </geometry>
            
        </collision>
        <xacro:inertial_sphere mass="0.1" radius="0.0575">
            <origin xyz="0 0 0" rpy="0 0 0"/>
        </xacro:inertial_sphere>
    </link>

    <!--BACK CASTER WHEEL LINK-->
    <joint name="back_caster_wheel_joint" type="fixed">
        <parent link="base_link"/>
        <child link="back_caster_wheel"/>
        <origin xyz="-0.1175 0 0"/>
    </joint>

    <link name="back_caster_wheel">
        <visual>
            <geometry>
                <sphere radius="0.0575"/>
            </geometry>
            <material name="black"/>
        </visual>
        <collision>
            <geometry>
                <sphere radius="0.0575"/>
            </geometry>
            
        </collision>
        <xacro:inertial_sphere mass="0.1" radius="0.0575">
            <origin xyz="0 0 0" rpy="0 0 0"/>
        </xacro:inertial_sphere>
    </link>

    <!--Laser-->

    <joint name="laser_joint" type="fixed">
        <parent link="chassis"/>
        <child link="laser"/>
        <origin xyz="0.28 0 0.28" rpy="0 0 0"/>
    </joint>

    <link name="laser">
        <visual>
            <geometry>
                <cylinder radius="0.05" length="0.05"/>
            </geometry>
            <material name="black"/>
        </visual>
        <visual>
            <origin xyz="0 0 -0.05"/>
            <geometry>
                <cylinder radius="0.01" length="0.1"/>
            </geometry>
            <material name="black"/>
        </visual>
        <collision>
            <geometry>
                <cylinder radius="0.05" length="0.05"/>
            </geometry>
        </collision>
        <xacro:inertial_cylinder mass="0.1" length="0.05" radius="0.05">
            <origin xyz="0 0 0" rpy="0 0 0"/>
        </xacro:inertial_cylinder>
    </link>

  <!-- <material name="orange">
    <color rgba="1.0 0.5 0.2 1" />
  </material>
  <material name="gray">
    <color rgba="0.2 0.2 0.2 1" />
  </material>

  <link name="laser">
    <visual>
      <origin xyz="0 0 0" />
      <geometry>
        <cylinder length="0.03" radius="0.03" />
      </geometry>
      <material name="gray" />
    </visual>
  </link>

  <link name="base_link">
    <visual>
      <origin xyz="0.01 0 0.015" />
      <geometry>
        <box size="0.11 0.065 0.052" />
      </geometry>
      <material name="orange" />
    </visual>
  </link>

  <joint name="laser_joint" type="fixed">
    <parent link="base_link" />
    <child link="laser" />
    <origin rpy="0 0 3.1415926" xyz="0 0 0.05" />
  </joint> -->

</robot>